[2025-07-01T22:52:02.280+0000] {local_task_job_runner.py:120} INFO - ::group::Pre task execution logs
[2025-07-01T22:52:02.339+0000] {taskinstance.py:2076} INFO - Dependencies all met for dep_context=non-requeueable deps ti=<TaskInstance: dbt_trino_silver_pipeline.dbt_run_silver scheduled__2025-07-01T22:50:00+00:00 [queued]>
[2025-07-01T22:52:02.355+0000] {taskinstance.py:2076} INFO - Dependencies all met for dep_context=requeueable deps ti=<TaskInstance: dbt_trino_silver_pipeline.dbt_run_silver scheduled__2025-07-01T22:50:00+00:00 [queued]>
[2025-07-01T22:52:02.356+0000] {taskinstance.py:2306} INFO - Starting attempt 1 of 1
[2025-07-01T22:52:02.376+0000] {taskinstance.py:2330} INFO - Executing <Task(DockerOperator): dbt_run_silver> on 2025-07-01 22:50:00+00:00
[2025-07-01T22:52:02.386+0000] {logging_mixin.py:188} WARNING - /home/airflow/.local/lib/python3.12/site-packages/airflow/task/task_runner/standard_task_runner.py:62 DeprecationWarning: This process (pid=372) is multi-threaded, use of fork() may lead to deadlocks in the child.
[2025-07-01T22:52:02.387+0000] {standard_task_runner.py:64} INFO - Started process 373 to run task
[2025-07-01T22:52:02.386+0000] {standard_task_runner.py:90} INFO - Running: ['airflow', 'tasks', 'run', 'dbt_trino_silver_pipeline', 'dbt_run_silver', 'scheduled__2025-07-01T22:50:00+00:00', '--job-id', '57', '--raw', '--subdir', 'DAGS_FOLDER/dbt_trino_silver_dag.py', '--cfg-path', '/tmp/tmpknx69xjs']
[2025-07-01T22:52:02.390+0000] {standard_task_runner.py:91} INFO - Job 57: Subtask dbt_run_silver
[2025-07-01T22:52:02.452+0000] {task_command.py:426} INFO - Running <TaskInstance: dbt_trino_silver_pipeline.dbt_run_silver scheduled__2025-07-01T22:50:00+00:00 [running]> on host 0a4aae371d36
[2025-07-01T22:52:02.571+0000] {taskinstance.py:2648} INFO - Exporting env vars: AIRFLOW_CTX_DAG_EMAIL='admin@example.com' AIRFLOW_CTX_DAG_OWNER='data-team' AIRFLOW_CTX_DAG_ID='dbt_trino_silver_pipeline' AIRFLOW_CTX_TASK_ID='dbt_run_silver' AIRFLOW_CTX_EXECUTION_DATE='2025-07-01T22:50:00+00:00' AIRFLOW_CTX_TRY_NUMBER='1' AIRFLOW_CTX_DAG_RUN_ID='scheduled__2025-07-01T22:50:00+00:00'
[2025-07-01T22:52:02.573+0000] {taskinstance.py:430} INFO - ::endgroup::
[2025-07-01T22:52:02.623+0000] {docker.py:367} INFO - Starting docker container from image modern-data-pipeline-dbt-trino:latest
[2025-07-01T22:52:02.966+0000] {docker.py:438} INFO - === Executando dbt run incremental ===
[2025-07-01T22:52:06.758+0000] {docker.py:438} INFO - [0m22:52:06  Running with dbt=1.7.0
[2025-07-01T22:52:07.206+0000] {docker.py:438} INFO - [0m22:52:07  Registered adapter: trino=1.7.0
[2025-07-01T22:52:07.250+0000] {docker.py:438} INFO - [0m22:52:07  Unable to do partial parsing because a project config has changed
[2025-07-01T22:52:09.242+0000] {docker.py:438} INFO - [0m22:52:09  Iniciando execu√ß√£o do dbt com Trino/Iceberg
[2025-07-01T22:52:09.286+0000] {docker.py:438} INFO - [0m22:52:09  Execu√ß√£o finalizada
[2025-07-01T22:52:09.937+0000] {docker.py:438} INFO - [0m22:52:09  Encountered an error:
[2025-07-01T22:52:09.937+0000] {docker.py:438} INFO - Compilation Error
[2025-07-01T22:52:09.937+0000] {docker.py:438} INFO -   dbt found two sources with the name "bronze_dados_produtores_agro".
[2025-07-01T22:52:09.937+0000] {docker.py:438} INFO -   
[2025-07-01T22:52:09.938+0000] {docker.py:438} INFO -   Since these resources have the same name, dbt will be unable to find the correct resource
[2025-07-01T22:52:09.938+0000] {docker.py:438} INFO -   when looking for source("bronze", "dados_produtores_agro").
[2025-07-01T22:52:09.938+0000] {docker.py:438} INFO -   
[2025-07-01T22:52:09.938+0000] {docker.py:438} INFO -   To fix this, change the name of one of these resources:
[2025-07-01T22:52:09.938+0000] {docker.py:438} INFO -   - source.agronegocio_iceberg.bronze.dados_produtores_agro (models/silver/schema.yml)
[2025-07-01T22:52:09.939+0000] {docker.py:438} INFO -   - source.agronegocio_iceberg.bronze.dados_produtores_agro (models/sources.yml)
[2025-07-01T22:52:11.287+0000] {taskinstance.py:441} INFO - ::group::Post task execution logs
[2025-07-01T22:52:11.317+0000] {taskinstance.py:2905} ERROR - Task failed with exception
Traceback (most recent call last):
  File "/home/airflow/.local/lib/python3.12/site-packages/airflow/models/taskinstance.py", line 460, in _execute_task
    result = _execute_callable(context=context, **execute_callable_kwargs)
             ^^^^^^^^^^^^^^^^^^^^^^^^^^^^^^^^^^^^^^^^^^^^^^^^^^^^^^^^^^^^^
  File "/home/airflow/.local/lib/python3.12/site-packages/airflow/models/taskinstance.py", line 432, in _execute_callable
    return execute_callable(context=context, **execute_callable_kwargs)
           ^^^^^^^^^^^^^^^^^^^^^^^^^^^^^^^^^^^^^^^^^^^^^^^^^^^^^^^^^^^^
  File "/home/airflow/.local/lib/python3.12/site-packages/airflow/models/baseoperator.py", line 401, in wrapper
    return func(self, *args, **kwargs)
           ^^^^^^^^^^^^^^^^^^^^^^^^^^^
  File "/home/airflow/.local/lib/python3.12/site-packages/airflow/providers/docker/operators/docker.py", line 513, in execute
    return self._run_image()
           ^^^^^^^^^^^^^^^^^
  File "/home/airflow/.local/lib/python3.12/site-packages/airflow/providers/docker/operators/docker.py", line 384, in _run_image
    return self._run_image_with_mounts(self.mounts, add_tmp_variable=False)
           ^^^^^^^^^^^^^^^^^^^^^^^^^^^^^^^^^^^^^^^^^^^^^^^^^^^^^^^^^^^^^^^^
  File "/home/airflow/.local/lib/python3.12/site-packages/airflow/providers/docker/operators/docker.py", line 446, in _run_image_with_mounts
    raise DockerContainerFailedException(f"Docker container failed: {result!r}", logs=log_lines)
airflow.providers.docker.exceptions.DockerContainerFailedException: Docker container failed: {'StatusCode': 2}
[2025-07-01T22:52:11.325+0000] {taskinstance.py:1206} INFO - Marking task as FAILED. dag_id=dbt_trino_silver_pipeline, task_id=dbt_run_silver, run_id=scheduled__2025-07-01T22:50:00+00:00, execution_date=20250701T225000, start_date=20250701T225202, end_date=20250701T225211
[2025-07-01T22:52:11.346+0000] {standard_task_runner.py:110} ERROR - Failed to execute job 57 for task dbt_run_silver (Docker container failed: {'StatusCode': 2}; 373)
[2025-07-01T22:52:11.396+0000] {local_task_job_runner.py:243} INFO - Task exited with return code 1
[2025-07-01T22:52:11.434+0000] {taskinstance.py:3503} INFO - 0 downstream tasks scheduled from follow-on schedule check
[2025-07-01T22:52:11.440+0000] {local_task_job_runner.py:222} INFO - ::endgroup::
