[2025-07-01T21:08:52.041+0000] {local_task_job_runner.py:120} INFO - ::group::Pre task execution logs
[2025-07-01T21:08:52.068+0000] {taskinstance.py:2076} INFO - Dependencies all met for dep_context=non-requeueable deps ti=<TaskInstance: dbt_trino_silver_pipeline.dbt_run_silver scheduled__2025-07-01T21:06:00+00:00 [queued]>
[2025-07-01T21:08:52.077+0000] {taskinstance.py:2076} INFO - Dependencies all met for dep_context=requeueable deps ti=<TaskInstance: dbt_trino_silver_pipeline.dbt_run_silver scheduled__2025-07-01T21:06:00+00:00 [queued]>
[2025-07-01T21:08:52.077+0000] {taskinstance.py:2306} INFO - Starting attempt 1 of 3
[2025-07-01T21:08:52.088+0000] {taskinstance.py:2330} INFO - Executing <Task(DockerOperator): dbt_run_silver> on 2025-07-01 21:06:00+00:00
[2025-07-01T21:08:52.095+0000] {logging_mixin.py:188} WARNING - /home/airflow/.local/lib/python3.12/site-packages/airflow/task/task_runner/standard_task_runner.py:62 DeprecationWarning: This process (pid=1507) is multi-threaded, use of fork() may lead to deadlocks in the child.
[2025-07-01T21:08:52.096+0000] {standard_task_runner.py:64} INFO - Started process 1508 to run task
[2025-07-01T21:08:52.095+0000] {standard_task_runner.py:90} INFO - Running: ['airflow', 'tasks', 'run', 'dbt_trino_silver_pipeline', 'dbt_run_silver', 'scheduled__2025-07-01T21:06:00+00:00', '--job-id', '199', '--raw', '--subdir', 'DAGS_FOLDER/dbt_trino_silver_dadg.py', '--cfg-path', '/tmp/tmpb_bsfq33']
[2025-07-01T21:08:52.097+0000] {standard_task_runner.py:91} INFO - Job 199: Subtask dbt_run_silver
[2025-07-01T21:08:52.135+0000] {task_command.py:426} INFO - Running <TaskInstance: dbt_trino_silver_pipeline.dbt_run_silver scheduled__2025-07-01T21:06:00+00:00 [running]> on host b4eeaef718a2
[2025-07-01T21:08:52.218+0000] {taskinstance.py:2648} INFO - Exporting env vars: AIRFLOW_CTX_DAG_EMAIL='admin@example.com' AIRFLOW_CTX_DAG_OWNER='data-team' AIRFLOW_CTX_DAG_ID='dbt_trino_silver_pipeline' AIRFLOW_CTX_TASK_ID='dbt_run_silver' AIRFLOW_CTX_EXECUTION_DATE='2025-07-01T21:06:00+00:00' AIRFLOW_CTX_TRY_NUMBER='1' AIRFLOW_CTX_DAG_RUN_ID='scheduled__2025-07-01T21:06:00+00:00'
[2025-07-01T21:08:52.218+0000] {taskinstance.py:430} INFO - ::endgroup::
[2025-07-01T21:08:52.249+0000] {docker.py:367} INFO - Starting docker container from image modern-data-pipeline-dbt-trino:latest
[2025-07-01T21:08:52.557+0000] {docker.py:438} INFO - === Executando dbt run incremental ===
[2025-07-01T21:08:55.464+0000] {docker.py:438} INFO - [0m21:08:55  Running with dbt=1.7.0
[2025-07-01T21:08:55.927+0000] {docker.py:438} INFO - [0m21:08:55  Registered adapter: trino=1.7.0
[2025-07-01T21:08:56.011+0000] {docker.py:438} INFO - [0m21:08:56  [[33mWARNING[0m]: Configuration paths exist in your dbt_project.yml file which do not apply to any resources.
[2025-07-01T21:08:56.011+0000] {docker.py:438} INFO - There are 1 unused configuration paths:
[2025-07-01T21:08:56.011+0000] {docker.py:438} INFO - - models.agronegocio_iceberg.staging
[2025-07-01T21:08:56.049+0000] {docker.py:438} INFO - [0m21:08:56  Found 1 model, 29 tests, 2 operations, 1 source, 0 exposures, 0 metrics, 427 macros, 0 groups, 0 semantic models
[2025-07-01T21:08:56.052+0000] {docker.py:438} INFO - [0m21:08:56
[2025-07-01T21:08:56.089+0000] {docker.py:438} INFO - [0m21:08:56
[2025-07-01T21:08:56.089+0000] {docker.py:438} INFO - [0m21:08:56  Finished running  in 0 hours 0 minutes and 0.04 seconds (0.04s).
[2025-07-01T21:08:56.090+0000] {docker.py:438} INFO - [0m21:08:56  Encountered an error:
[2025-07-01T21:08:56.090+0000] {docker.py:438} INFO - Database Error
[2025-07-01T21:08:56.091+0000] {docker.py:438} INFO -   TrinoUserError(type=USER_ERROR, name=INVALID_SESSION_PROPERTY, message="Unknown session property exchange_compression", query_id=20250701_210856_00057_yqvmp)
[2025-07-01T21:08:56.708+0000] {docker.py:438} INFO - Traceback (most recent call last):
[2025-07-01T21:08:56.709+0000] {docker.py:438} INFO -   File "/usr/local/lib/python3.9/site-packages/dbt/adapters/trino/connections.py", line 399, in exception_handler
[2025-07-01T21:08:56.710+0000] {docker.py:438} INFO - yield
[2025-07-01T21:08:56.711+0000] {docker.py:438} INFO -   File "/usr/local/lib/python3.9/site-packages/dbt/adapters/sql/connections.py", line 80, in add_query
[2025-07-01T21:08:56.712+0000] {docker.py:438} INFO - cursor.execute(sql, bindings)
[2025-07-01T21:08:56.712+0000] {docker.py:438} INFO -   File "/usr/local/lib/python3.9/site-packages/dbt/adapters/trino/connections.py", line 355, in execute
[2025-07-01T21:08:56.713+0000] {docker.py:438} INFO - result = self._cursor.execute(sql, params=bindings)
[2025-07-01T21:08:56.714+0000] {docker.py:438} INFO -   File "/usr/local/lib/python3.9/site-packages/trino/dbapi.py", line 640, in execute
[2025-07-01T21:08:56.715+0000] {docker.py:438} INFO - self._iterator = iter(self._query.execute())
[2025-07-01T21:08:56.715+0000] {docker.py:438} INFO -   File "/usr/local/lib/python3.9/site-packages/trino/client.py", line 900, in execute
[2025-07-01T21:08:56.716+0000] {docker.py:438} INFO - self._result.rows += self.fetch()
[2025-07-01T21:08:56.717+0000] {docker.py:438} INFO -   File "/usr/local/lib/python3.9/site-packages/trino/client.py", line 920, in fetch
[2025-07-01T21:08:56.717+0000] {docker.py:438} INFO - status = self._request.process(response)
[2025-07-01T21:08:56.718+0000] {docker.py:438} INFO -   File "/usr/local/lib/python3.9/site-packages/trino/client.py", line 689, in process
[2025-07-01T21:08:56.719+0000] {docker.py:438} INFO - raise self._process_error(response["error"], response.get("id"))
[2025-07-01T21:08:56.721+0000] {docker.py:438} INFO - trino.exceptions.TrinoUserError: TrinoUserError(type=USER_ERROR, name=INVALID_SESSION_PROPERTY, message="Unknown session property exchange_compression", query_id=20250701_210856_00057_yqvmp)
[2025-07-01T21:08:56.722+0000] {docker.py:438} INFO - 
[2025-07-01T21:08:56.722+0000] {docker.py:438} INFO - During handling of the above exception, another exception occurred:
[2025-07-01T21:08:56.723+0000] {docker.py:438} INFO - 
[2025-07-01T21:08:56.724+0000] {docker.py:438} INFO - Traceback (most recent call last):
[2025-07-01T21:08:56.725+0000] {docker.py:438} INFO -   File "/usr/local/lib/python3.9/site-packages/dbt/cli/requires.py", line 90, in wrapper
[2025-07-01T21:08:56.726+0000] {docker.py:438} INFO - result, success = func(*args, **kwargs)
[2025-07-01T21:08:56.727+0000] {docker.py:438} INFO -   File "/usr/local/lib/python3.9/site-packages/dbt/cli/requires.py", line 75, in wrapper
[2025-07-01T21:08:56.728+0000] {docker.py:438} INFO - return func(*args, **kwargs)
[2025-07-01T21:08:56.729+0000] {docker.py:438} INFO -   File "/usr/local/lib/python3.9/site-packages/dbt/cli/requires.py", line 168, in wrapper
[2025-07-01T21:08:56.730+0000] {docker.py:438} INFO - return func(*args, **kwargs)
[2025-07-01T21:08:56.730+0000] {docker.py:438} INFO -   File "/usr/local/lib/python3.9/site-packages/dbt/cli/requires.py", line 197, in wrapper
[2025-07-01T21:08:56.731+0000] {docker.py:438} INFO - return func(*args, **kwargs)
[2025-07-01T21:08:56.732+0000] {docker.py:438} INFO -   File "/usr/local/lib/python3.9/site-packages/dbt/cli/requires.py", line 244, in wrapper
[2025-07-01T21:08:56.733+0000] {docker.py:438} INFO - return func(*args, **kwargs)
[2025-07-01T21:08:56.733+0000] {docker.py:438} INFO -   File "/usr/local/lib/python3.9/site-packages/dbt/cli/requires.py", line 284, in wrapper
[2025-07-01T21:08:56.734+0000] {docker.py:438} INFO - return func(*args, **kwargs)
[2025-07-01T21:08:56.735+0000] {docker.py:438} INFO -   File "/usr/local/lib/python3.9/site-packages/dbt/cli/main.py", line 625, in run
[2025-07-01T21:08:56.736+0000] {docker.py:438} INFO - results = task.run()
[2025-07-01T21:08:56.736+0000] {docker.py:438} INFO -   File "/usr/local/lib/python3.9/site-packages/dbt/task/runnable.py", line 474, in run
[2025-07-01T21:08:56.737+0000] {docker.py:438} INFO - result = self.execute_with_hooks(selected_uids)
[2025-07-01T21:08:56.738+0000] {docker.py:438} INFO -   File "/usr/local/lib/python3.9/site-packages/dbt/task/runnable.py", line 434, in execute_with_hooks
[2025-07-01T21:08:56.739+0000] {docker.py:438} INFO - self.before_run(adapter, selected_uids)
[2025-07-01T21:08:56.739+0000] {docker.py:438} INFO -   File "/usr/local/lib/python3.9/site-packages/dbt/task/run.py", line 446, in before_run
[2025-07-01T21:08:56.740+0000] {docker.py:438} INFO - self.create_schemas(adapter, required_schemas)
[2025-07-01T21:08:56.741+0000] {docker.py:438} INFO - File "/usr/local/lib/python3.9/site-packages/dbt/task/runnable.py", line 573, in create_schemas
[2025-07-01T21:08:56.742+0000] {docker.py:438} INFO - existing_schemas_lowered.update(ls_future.result())
[2025-07-01T21:08:56.743+0000] {docker.py:438} INFO -   File "/usr/local/lib/python3.9/concurrent/futures/_base.py", line 439, in result
[2025-07-01T21:08:56.743+0000] {docker.py:438} INFO - return self.__get_result()
[2025-07-01T21:08:56.744+0000] {docker.py:438} INFO -   File "/usr/local/lib/python3.9/concurrent/futures/_base.py", line 391, in __get_result
[2025-07-01T21:08:56.745+0000] {docker.py:438} INFO -     raise self._exception
[2025-07-01T21:08:56.745+0000] {docker.py:438} INFO -   File "/usr/local/lib/python3.9/concurrent/futures/thread.py", line 58, in run
[2025-07-01T21:08:56.746+0000] {docker.py:438} INFO -     result = self.fn(*self.args, **self.kwargs)
[2025-07-01T21:08:56.747+0000] {docker.py:438} INFO -   File "/usr/local/lib/python3.9/site-packages/dbt/utils.py", line 471, in connected
[2025-07-01T21:08:56.747+0000] {docker.py:438} INFO -     return func(*args, **kwargs)
[2025-07-01T21:08:56.748+0000] {docker.py:438} INFO -   File "/usr/local/lib/python3.9/site-packages/dbt/task/runnable.py", line 550, in list_schemas
[2025-07-01T21:08:56.748+0000] {docker.py:438} INFO -     for s in adapter.list_schemas(database_quoted)
[2025-07-01T21:08:56.749+0000] {docker.py:438} INFO -   File "/usr/local/lib/python3.9/site-packages/dbt/adapters/sql/impl.py", line 206, in list_schemas
[2025-07-01T21:08:56.750+0000] {docker.py:438} INFO -     results = self.execute_macro(LIST_SCHEMAS_MACRO_NAME, kwargs={"database": database})
[2025-07-01T21:08:56.750+0000] {docker.py:438} INFO -   File "/usr/local/lib/python3.9/site-packages/dbt/adapters/base/impl.py", line 1099, in execute_macro
[2025-07-01T21:08:56.752+0000] {docker.py:438} INFO - result = macro_function(**kwargs)
[2025-07-01T21:08:56.753+0000] {docker.py:438} INFO - File "/usr/local/lib/python3.9/site-packages/dbt/clients/jinja.py", line 330, in __call__
[2025-07-01T21:08:56.753+0000] {docker.py:438} INFO - return self.call_macro(*args, **kwargs)
[2025-07-01T21:08:56.754+0000] {docker.py:438} INFO - File "/usr/local/lib/python3.9/site-packages/dbt/clients/jinja.py", line 257, in call_macro
[2025-07-01T21:08:56.755+0000] {docker.py:438} INFO - return macro(*args, **kwargs)
[2025-07-01T21:08:56.756+0000] {docker.py:438} INFO -   File "/usr/local/lib/python3.9/site-packages/jinja2/runtime.py", line 770, in __call__
[2025-07-01T21:08:56.757+0000] {docker.py:438} INFO - return self._invoke(arguments, autoescape)
[2025-07-01T21:08:56.758+0000] {docker.py:438} INFO -   File "/usr/local/lib/python3.9/site-packages/jinja2/runtime.py", line 784, in _invoke
[2025-07-01T21:08:56.759+0000] {docker.py:438} INFO - rv = self._func(*arguments)
[2025-07-01T21:08:56.759+0000] {docker.py:438} INFO -   File "<template>", line 20, in macro
[2025-07-01T21:08:56.760+0000] {docker.py:438} INFO - File "/usr/local/lib/python3.9/site-packages/jinja2/sandbox.py", line 401, in call
[2025-07-01T21:08:56.761+0000] {docker.py:438} INFO - return __context.call(__obj, *args, **kwargs)
[2025-07-01T21:08:56.762+0000] {docker.py:438} INFO -   File "/usr/local/lib/python3.9/site-packages/jinja2/runtime.py", line 303, in call
[2025-07-01T21:08:56.763+0000] {docker.py:438} INFO - return __obj(*args, **kwargs)
[2025-07-01T21:08:56.763+0000] {docker.py:438} INFO -   File "/usr/local/lib/python3.9/site-packages/dbt/clients/jinja.py", line 330, in __call__
[2025-07-01T21:08:56.764+0000] {docker.py:438} INFO - return self.call_macro(*args, **kwargs)
[2025-07-01T21:08:56.765+0000] {docker.py:438} INFO -   File "/usr/local/lib/python3.9/site-packages/dbt/clients/jinja.py", line 257, in call_macro
[2025-07-01T21:08:56.766+0000] {docker.py:438} INFO - return macro(*args, **kwargs)
[2025-07-01T21:08:56.767+0000] {docker.py:438} INFO -   File "/usr/local/lib/python3.9/site-packages/jinja2/runtime.py", line 770, in __call__
[2025-07-01T21:08:56.767+0000] {docker.py:438} INFO - return self._invoke(arguments, autoescape)
[2025-07-01T21:08:56.768+0000] {docker.py:438} INFO -   File "/usr/local/lib/python3.9/site-packages/jinja2/runtime.py", line 784, in _invoke
[2025-07-01T21:08:56.769+0000] {docker.py:438} INFO - rv = self._func(*arguments)
[2025-07-01T21:08:56.770+0000] {docker.py:438} INFO -   File "<template>", line 31, in macro
[2025-07-01T21:08:56.771+0000] {docker.py:438} INFO - File "/usr/local/lib/python3.9/site-packages/jinja2/sandbox.py", line 401, in call
[2025-07-01T21:08:56.771+0000] {docker.py:438} INFO - return __context.call(__obj, *args, **kwargs)
[2025-07-01T21:08:56.772+0000] {docker.py:438} INFO -   File "/usr/local/lib/python3.9/site-packages/jinja2/runtime.py", line 303, in call
[2025-07-01T21:08:56.773+0000] {docker.py:438} INFO - return __obj(*args, **kwargs)
[2025-07-01T21:08:56.774+0000] {docker.py:438} INFO -   File "/usr/local/lib/python3.9/site-packages/dbt/clients/jinja.py", line 330, in __call__
[2025-07-01T21:08:56.774+0000] {docker.py:438} INFO - return self.call_macro(*args, **kwargs)
[2025-07-01T21:08:56.775+0000] {docker.py:438} INFO -   File "/usr/local/lib/python3.9/site-packages/dbt/clients/jinja.py", line 257, in call_macro
[2025-07-01T21:08:56.776+0000] {docker.py:438} INFO - return macro(*args, **kwargs)
[2025-07-01T21:08:56.777+0000] {docker.py:438} INFO -   File "/usr/local/lib/python3.9/site-packages/jinja2/runtime.py", line 770, in __call__
[2025-07-01T21:08:56.777+0000] {docker.py:438} INFO - return self._invoke(arguments, autoescape)
[2025-07-01T21:08:56.778+0000] {docker.py:438} INFO -   File "/usr/local/lib/python3.9/site-packages/jinja2/runtime.py", line 784, in _invoke
[2025-07-01T21:08:56.779+0000] {docker.py:438} INFO - rv = self._func(*arguments)
[2025-07-01T21:08:56.780+0000] {docker.py:438} INFO -   File "<template>", line 52, in macro
[2025-07-01T21:08:56.780+0000] {docker.py:438} INFO - File "/usr/local/lib/python3.9/site-packages/jinja2/sandbox.py", line 401, in call
[2025-07-01T21:08:56.781+0000] {docker.py:438} INFO - return __context.call(__obj, *args, **kwargs)
[2025-07-01T21:08:56.782+0000] {docker.py:438} INFO -   File "/usr/local/lib/python3.9/site-packages/jinja2/runtime.py", line 303, in call
[2025-07-01T21:08:56.782+0000] {docker.py:438} INFO - return __obj(*args, **kwargs)
[2025-07-01T21:08:56.783+0000] {docker.py:438} INFO -   File "/usr/local/lib/python3.9/site-packages/dbt/adapters/base/impl.py", line 309, in execute
[2025-07-01T21:08:56.784+0000] {docker.py:438} INFO - return self.connections.execute(sql=sql, auto_begin=auto_begin, fetch=fetch, limit=limit)
[2025-07-01T21:08:56.785+0000] {docker.py:438} INFO -   File "/usr/local/lib/python3.9/site-packages/dbt/adapters/sql/connections.py", line 138, in execute
[2025-07-01T21:08:56.786+0000] {docker.py:438} INFO - _, cursor = self.add_query(sql, auto_begin)
[2025-07-01T21:08:56.786+0000] {docker.py:438} INFO -   File "/usr/local/lib/python3.9/site-packages/dbt/adapters/trino/connections.py", line 497, in add_query
[2025-07-01T21:08:56.787+0000] {docker.py:438} INFO - connection, cursor = parent.add_query(
[2025-07-01T21:08:56.788+0000] {docker.py:438} INFO -   File "/usr/local/lib/python3.9/site-packages/dbt/adapters/sql/connections.py", line 90, in add_query
[2025-07-01T21:08:56.789+0000] {docker.py:438} INFO - return connection, cursor
[2025-07-01T21:08:56.789+0000] {docker.py:438} INFO -   File "/usr/local/lib/python3.9/contextlib.py", line 137, in __exit__
[2025-07-01T21:08:56.790+0000] {docker.py:438} INFO - self.gen.throw(typ, value, traceback)
[2025-07-01T21:08:56.791+0000] {docker.py:438} INFO -   File "/usr/local/lib/python3.9/site-packages/dbt/adapters/trino/connections.py", line 410, in exception_handler
[2025-07-01T21:08:56.791+0000] {docker.py:438} INFO - raise DbtDatabaseError(msg)
[2025-07-01T21:08:56.792+0000] {docker.py:438} INFO - dbt.exceptions.DbtDatabaseError: Database Error
[2025-07-01T21:08:56.793+0000] {docker.py:438} INFO -   TrinoUserError(type=USER_ERROR, name=INVALID_SESSION_PROPERTY, message="Unknown session property exchange_compression", query_id=20250701_210856_00057_yqvmp)
[2025-07-01T21:08:56.793+0000] {docker.py:438} INFO - 
[2025-07-01T21:08:56.794+0000] {docker.py:438} INFO - During handling of the above exception, another exception occurred:
[2025-07-01T21:08:56.795+0000] {docker.py:438} INFO - 
[2025-07-01T21:08:56.795+0000] {docker.py:438} INFO - Traceback (most recent call last):
[2025-07-01T21:08:56.796+0000] {docker.py:438} INFO -   File "/usr/local/lib/python3.9/site-packages/dbt/cli/requires.py", line 96, in wrapper
[2025-07-01T21:08:56.796+0000] {docker.py:438} INFO -     raise ExceptionExit(e)
[2025-07-01T21:08:56.797+0000] {docker.py:438} INFO - dbt.cli.exceptions.ExceptionExit: <exception str() failed>
[2025-07-01T21:08:56.798+0000] {docker.py:438} INFO - 
[2025-07-01T21:08:56.798+0000] {docker.py:438} INFO - During handling of the above exception, another exception occurred:
[2025-07-01T21:08:56.799+0000] {docker.py:438} INFO - 
[2025-07-01T21:08:56.800+0000] {docker.py:438} INFO - Traceback (most recent call last):
[2025-07-01T21:08:56.800+0000] {docker.py:438} INFO -   File "/usr/local/bin/dbt", line 8, in <module>
[2025-07-01T21:08:56.801+0000] {docker.py:438} INFO -     sys.exit(cli())
[2025-07-01T21:08:56.802+0000] {docker.py:438} INFO -   File "/usr/local/lib/python3.9/site-packages/click/core.py", line 1161, in __call__
[2025-07-01T21:08:56.802+0000] {docker.py:438} INFO - return self.main(*args, **kwargs)
[2025-07-01T21:08:56.803+0000] {docker.py:438} INFO -   File "/usr/local/lib/python3.9/site-packages/click/core.py", line 1082, in main
[2025-07-01T21:08:56.804+0000] {docker.py:438} INFO - rv = self.invoke(ctx)
[2025-07-01T21:08:56.805+0000] {docker.py:438} INFO -   File "/usr/local/lib/python3.9/site-packages/click/core.py", line 1697, in invoke
[2025-07-01T21:08:56.806+0000] {docker.py:438} INFO - return _process_result(sub_ctx.command.invoke(sub_ctx))
[2025-07-01T21:08:56.806+0000] {docker.py:438} INFO -   File "/usr/local/lib/python3.9/site-packages/click/core.py", line 1443, in invoke
[2025-07-01T21:08:56.807+0000] {docker.py:438} INFO - return ctx.invoke(self.callback, **ctx.params)
[2025-07-01T21:08:56.808+0000] {docker.py:438} INFO -   File "/usr/local/lib/python3.9/site-packages/click/core.py", line 788, in invoke
[2025-07-01T21:08:56.808+0000] {docker.py:438} INFO - return __callback(*args, **kwargs)
[2025-07-01T21:08:56.809+0000] {docker.py:438} INFO -   File "/usr/local/lib/python3.9/site-packages/click/decorators.py", line 33, in new_func
[2025-07-01T21:08:56.810+0000] {docker.py:438} INFO - return f(get_current_context(), *args, **kwargs)
[2025-07-01T21:08:56.810+0000] {docker.py:438} INFO -   File "/usr/local/lib/python3.9/site-packages/dbt/cli/main.py", line 155, in wrapper
[2025-07-01T21:08:56.811+0000] {docker.py:438} INFO - return func(*args, **kwargs)
[2025-07-01T21:08:56.811+0000] {docker.py:438} INFO -   File "/usr/local/lib/python3.9/site-packages/dbt/cli/requires.py", line 108, in wrapper
[2025-07-01T21:08:56.812+0000] {docker.py:438} INFO - fire_event(
[2025-07-01T21:08:56.812+0000] {docker.py:438} INFO -   File "/usr/local/lib/python3.9/site-packages/dbt/events/functions.py", line 270, in fire_event
[2025-07-01T21:08:56.813+0000] {docker.py:438} INFO - EVENT_MANAGER.fire_event(e, level=level)
[2025-07-01T21:08:56.813+0000] {docker.py:438} INFO -   File "/usr/local/lib/python3.9/site-packages/dbt/events/eventmgr.py", line 17, in fire_event
[2025-07-01T21:08:56.814+0000] {docker.py:438} INFO - msg = msg_from_base_event(e, level=level)
[2025-07-01T21:08:56.814+0000] {docker.py:438} INFO -   File "/usr/local/lib/python3.9/site-packages/dbt/events/base_types.py", line 143, in msg_from_base_event
[2025-07-01T21:08:56.815+0000] {docker.py:438} INFO -     "msg": event.message(),
[2025-07-01T21:08:56.815+0000] {docker.py:438} INFO -   File "/usr/local/lib/python3.9/site-packages/dbt/events/types.py", line 2403, in message
[2025-07-01T21:08:56.816+0000] {docker.py:438} INFO - return f"Resource report: {self.to_json()}"
[2025-07-01T21:08:56.816+0000] {docker.py:438} INFO -   File "/usr/local/lib/python3.9/site-packages/dbt/events/base_types.py", line 104, in to_json
[2025-07-01T21:08:56.817+0000] {docker.py:438} INFO - return MessageToJson(
[2025-07-01T21:08:56.817+0000] {docker.py:438} INFO - TypeError: MessageToJson() got an unexpected keyword argument 'including_default_value_fields'
[2025-07-01T21:08:57.233+0000] {taskinstance.py:441} INFO - ::group::Post task execution logs
[2025-07-01T21:08:57.240+0000] {taskinstance.py:2905} ERROR - Task failed with exception
Traceback (most recent call last):
  File "/home/airflow/.local/lib/python3.12/site-packages/airflow/models/taskinstance.py", line 460, in _execute_task
    result = _execute_callable(context=context, **execute_callable_kwargs)
             ^^^^^^^^^^^^^^^^^^^^^^^^^^^^^^^^^^^^^^^^^^^^^^^^^^^^^^^^^^^^^
  File "/home/airflow/.local/lib/python3.12/site-packages/airflow/models/taskinstance.py", line 432, in _execute_callable
    return execute_callable(context=context, **execute_callable_kwargs)
           ^^^^^^^^^^^^^^^^^^^^^^^^^^^^^^^^^^^^^^^^^^^^^^^^^^^^^^^^^^^^
  File "/home/airflow/.local/lib/python3.12/site-packages/airflow/models/baseoperator.py", line 401, in wrapper
    return func(self, *args, **kwargs)
           ^^^^^^^^^^^^^^^^^^^^^^^^^^^
  File "/home/airflow/.local/lib/python3.12/site-packages/airflow/providers/docker/operators/docker.py", line 513, in execute
    return self._run_image()
           ^^^^^^^^^^^^^^^^^
  File "/home/airflow/.local/lib/python3.12/site-packages/airflow/providers/docker/operators/docker.py", line 384, in _run_image
    return self._run_image_with_mounts(self.mounts, add_tmp_variable=False)
           ^^^^^^^^^^^^^^^^^^^^^^^^^^^^^^^^^^^^^^^^^^^^^^^^^^^^^^^^^^^^^^^^
  File "/home/airflow/.local/lib/python3.12/site-packages/airflow/providers/docker/operators/docker.py", line 446, in _run_image_with_mounts
    raise DockerContainerFailedException(f"Docker container failed: {result!r}", logs=log_lines)
airflow.providers.docker.exceptions.DockerContainerFailedException: Docker container failed: {'StatusCode': 1}
[2025-07-01T21:08:57.244+0000] {taskinstance.py:1206} INFO - Marking task as UP_FOR_RETRY. dag_id=dbt_trino_silver_pipeline, task_id=dbt_run_silver, run_id=scheduled__2025-07-01T21:06:00+00:00, execution_date=20250701T210600, start_date=20250701T210852, end_date=20250701T210857
[2025-07-01T21:08:57.255+0000] {standard_task_runner.py:110} ERROR - Failed to execute job 199 for task dbt_run_silver (Docker container failed: {'StatusCode': 1}; 1508)
[2025-07-01T21:08:57.264+0000] {local_task_job_runner.py:243} INFO - Task exited with return code 1
[2025-07-01T21:08:57.282+0000] {taskinstance.py:3503} INFO - 0 downstream tasks scheduled from follow-on schedule check
[2025-07-01T21:08:57.284+0000] {local_task_job_runner.py:222} INFO - ::endgroup::
